Workbook

Sheet Contratos aprendizaje
A1: ASIGNACIÓN DE INSTRUCTOR DE SEGUIMIENTO A APRENDICES CON CONTRATO DE APRENDIZAJE
A2: INSTRUCTOR | B2: NIT | C2: Razon Social | D2: Departamento empresa | E2: Ciudad empresa | F2: Dirección | G2: Teléfono empresa | H2: Correo electrónico | I2: Tipo documento | J2: Numero documento | K2: Apellidos | L2: Nombres | M2: Fecha Nacimiento | N2: Género | O2: Discapacidad | P2: Teléfono | Q2: Correo electónico | R2: Departamento código | S2: Departamento | T2: Municipio código | U2: Municipio | V2: Centro ID | W2: Centro | X2: Especialidad | Y2: Ficha | Z2: Inicio lectiva | AA2: Fin lectiva | AB2: Inicio productiva | AC2: Fin productiva | AD2: Contrato inicio | AE2: Contrato Fin | AF2: Regional | AG2: Fase | AH2: Nit EPS | AI2: EPS | AJ2: Nit ARL | AK2: ARL | AL2: Fecha registro | AM2: Contrato cedido a | AN2: Causa de finalización del contrato | AO2: Detalle de finalización del contrato | AP2: Ciudad última solicitud
A3: Andres Cataño | B3: 800021137 | C3: AGRICOLA SARA PALMA S.A. | D3: ANTIOQUIA | E3: MEDELLIN | F3: apartado | G3: 3103531316 | H3: Mzapata@sarapalma.com.co | I3: C.C. | J3: 1027948187 | K3: MOSQUERA MARMOLEJO | L3: YURIS LENYS | M3: 20/04/2005 | N3: F | P3: 5713333333 | Q3: yurismosquera124@gmail.com | R3: 5 | S3: ANTIOQUIA | T3: 147 | U3: CAREPA | V3: 950400 | W3: COMPLEJO TECNOLOGICO AGROINDUSTRIAL,PECUARIO Y TURISTICO -URABA- | X3: TECNICO EN PRODUCCION AGROPECUARIA | Y3: 2818005 | Z3: 04/08/2023 | AA3: 04/05/2024 | AB3: 05/05/2024 | AC3: 05/11/2024 | AD3: 25/10/2023 | AE3: 46004 | AF3: REGIONAL ANTIOQUIA | AG3: LECTIVA - PRODUCTIVA | AH3: 800088702 | AI3: EPS SURA | AJ3: 999999999 | AK3: No registrada | AL3: 45229.419 | AN3: Terminación automática por fecha de contrato Automatic Job1
A4: Dina Dorado | B4: 890930060 | C4: AGRICOLA SANTAMARIA S.A.S | D4: ANTIOQUIA | E4: APARTADO | F4: KM 1 SALIDA TURBO, BODEGAS TROPICENTRO | G4: 3197060-8156020-3207252274 | H4: rocio.valencia@gruposantamaria.com.co, comiteintegral@gruposantamaria.com.co | I4: T.I. | J4: 1028012740 | K4: GUZMAN VUELVAS | L4: VALENTINA | M4: 39192 | N4: F | P4: 573126158300 | Q4: valentina2006guz@gmail.com | R4: 5 | S4: ANTIOQUIA | T4: 313 | U4: GRANADA | V4: 950400 | W4: COMPLEJO TECNOLOGICO AGROINDUSTRIAL,PECUARIO Y TURISTICO -URABA- | X4: TECNICO EN PRODUCCION AGROPECUARIA | Y4: 2987617 | Z4: 45426 | AA4: 45743 | AB4: 45744 | AC4: 45926 | AD4: 45824 | AE4: 46006 | AF4: REGIONAL ANTIOQUIA | AG4: PRODUCTIVA | AH4: 890900286 | AI4: SAVIA SALUD E.P.S. | AJ4: 800256161 | AK4: ARP SURA | AL4: 45824.665
A5: Andrés Felipe Henao | B5: 900614404 | C5: BIOPLANTA PALMERA PARA EL DESARROLLO S.A. | D5: ANTIOQUIA | E5: CAREPA | F5: CR 80 CL 80 CENTRO COMERCIAL LAS PLAYAS BL 1 | G5: 8155970 | H5: nomina@bioplanta.co | I5: C.C. | J5: 1027943775 | K5: LOPEZ GARCIA | L5: JUAN DAVID | M5: 06/08/2004 | N5: M | P5: 573117821565 | Q5: juandavidlopezgarcia225@gmail.com | R5: 5 | S5: ANTIOQUIA | T5: 45 | U5: APARTADO | V5: 950400 | W5: COMPLEJO TECNOLOGICO AGROINDUSTRIAL,PECUARIO Y TURISTICO -URABA- | X5: TÉCNICO EN MECANICA DE MAQUINARIA INDUSTRIAL | Y5: 2924270 | Z5: 15/04/2024 | AA5: 28/02/2025 | AB5: 01/03/2025 | AC5: 30/08/2025 | AD5: 27/08/2025 | AE5: 46006 | AF5: REGIONAL ANTIOQUIA | AG5: PRODUCTIVA | AH5: 890900286 | AI5: SAVIA SALUD E.P.S. | AJ5: 860028415 | AK5: SEGUROS LA EQUIDAD | AL5: 45896.458
A6: Andres Cataño | B6: 900089324 | C6: AGRICOLA MAYORCA S.A. | D6: ANTIOQUIA | E6: MEDELLIN | F6: CARRERA 43A No. 19-17 EDIFICIO BLOCK EMPRESARIAL PISO 12 | G6: 4440009 - 8243483 (URABA) | H6: analistacontrataciones@banafrut.com | I6: C.C. | J6: 1028030571 | K6: SEPULVEDA MONROY | L6: GABRIELA MARIA | M6: 35398 | N6: F | P6: 573100472329 | Q6: gabrielasepulveda2024@gmail.com | R6: 5 | S6: ANTIOQUIA | T6: 45 | U6: APARTADO | V6: 950400 | W6: COMPLEJO TECNOLOGICO AGROINDUSTRIAL,PECUARIO Y TURISTICO -URABA- | X6: TECNICO EN PRODUCCION AGROPECUARIA | Y6: 3046758 | Z6: 45520 | AA6: 45793 | AB6: 45794 | AC6: 45976 | AD6: 45824 | AE6: 46007 | AF6: REGIONAL ANTIOQUIA | AG6: PRODUCTIVA | AH6: 800088702 | AI6: EPS SURA | AJ6: 800256161 | AK6: ARP SURA | AL6: 45824.294
A7: Abel Valderrama | B7: 811009784 | C7: BANANERAS FUEGO VERDE S.A. | D7: ANTIOQUIA | E7: MEDELLIN | F7: Cr 99 entre cl 99b 100 | G7: 8156235 - 3162510723 | H7: bienestarlaboral@grupo20sa.com | I7: C.C. | J7: 1040356203 | K7: MARTINEZ CERVANTES | L7: JHEIDER ANTONIO | M7: 08/04/2006 | N7: M | P7: 573107447313 | Q7: martinezjhoimer3@gmail.com | R7: 5 | S7: ANTIOQUIA | T7: 147 | U7: CAREPA | V7: 950400 | W7: COMPLEJO TECNOLOGICO AGROINDUSTRIAL,PECUARIO Y TURISTICO -URABA- | X7: TÉCNICO EN SISTEMAS TELEINFORMÁTICOS | Y7: 3077813 | Z7: 16/09/2024 | AA7: 16/06/2025 | AB7: 17/06/2025 | AC7: 15/12/2025 | AD7: 28/11/2024 | AE7: 46007 | AF7: REGIONAL ANTIOQUIA | AG7: LECTIVA - PRODUCTIVA | AH7: 900156264 | AI7: NUEVA EPS | AJ7: 860013816 | AK7: POSITIVA | AL7: 45624.339
A8: Virtual | B8: 900727452 | C8: ECOLIMPIEZA SOLUCIONES EMPRESARIALES S.A.S. | D8: TOLIMA | E8: IBAGUE | F8: CL 12 N 3 - 65 IN 5 | G8: 3184631920 | H8: ecolimpiezaibague@hotmail.com | I8: C.C. | J8: 1107975931 | K8: URIBE PAEZ | L8: DUVAN ALEXIS | M8: 18/05/2005 | N8: M | P8: 573123115278 | Q8: duvanalexisu@gmail.com | R8: 73 | S8: TOLIMA | T8: 1 | U8: IBAGUE | V8: 950400 | W8: COMPLEJO TECNOLOGICO AGROINDUSTRIAL,PECUARIO Y TURISTICO -URABA- | X8: TÉCNICO EN INTEGRACION DE CONTENIDOS DIGITALES. | Y8: 2721391 | Z8: 27/03/2023 | AA8: 27/12/2023 | AB8: 28/12/2023 | AC8: 26/06/2024 | AD8: 16/06/2025 | AE8: 46007 | AF8: REGIONAL ANTIOQUIA | AG8: PRODUCTIVA | AH8: 900156264 | AI8: NUEVA EPS | AJ8: 800256161 | AK8: ARP SURA | AL8: 45824.569 | AN8: Terminación automática por fecha de contrato Automatic Job1
A9: Virtual | B9: 901420688 | C9: KONFÍE S.A.S. | D9: BOGOTA D.C. | E9: BOGOTA D. C. | F9: Calle 17 A No. 68 D - 17 | G9: 3202256593 | H9: talento.humano@konfie.com | I9: C.C. | J9: 1018485900 | K9: RODRIGUEZ YASNO | L9: DANIELA ALEXANDRA | M9: 35204 | N9: F | P9: 3206253344 | Q9: drodriguez_19@outlook.com | R9: 11 | S9: BOGOTA D.C. | T9: 1 | U9: BOGOTA D. C. | V9: 950400 | W9: COMPLEJO TECNOLOGICO AGROINDUSTRIAL,PECUARIO Y TURISTICO -URABA- | X9: TÉCNICO EN ATENCION INTEGRAL AL CLIENTE | Y9: 3069862 | Z9: 45551 | AA9: 45824 | AB9: 45825 | AC9: 46006 | AD9: 45882 | AE9: 46009 | AF9: REGIONAL ANTIOQUIA | AG9: PRODUCTIVA | AH9: 860066942 | AI9: COMPENSAR E.P.S. | AJ9: 860002503 | AK9: COMPAÑÍA DE SEGUROS BOLIVAR | AL9: 45882.431
A10: Abel Valderrama | B10: 890929329 | C10: SUPERMERCADO LOS IBAÑEZ Y COMPAÑÍA S.A. | D10: ANTIOQUIA | E10: APARTADO | F10: CALLE 99 No 102-55 Barrio Ortiz | G10: 3128322234 | H10: LOSIBANEZSUPER@HOTMAIL.COM | I10: C.C. | J10: 1040381543 | K10: SANCHEZ BURGOS | L10: MERLYS JOHANA | M10: 35992 | N10: F | P10: 3009662320 | Q10: merlissanchez104@gmail.com | R10: 5 | S10: ANTIOQUIA | T10: 147 | U10: CAREPA | V10: 950400 | W10: COMPLEJO TECNOLOGICO AGROINDUSTRIAL,PECUARIO Y TURISTICO -URABA- | X10: TÉCNICO EN SISTEMAS TELEINFORMÁTICOS | Y10: 2975578 | Z10: 45406 | AA10: 45681 | AB10: 45682 | AC10: 45861 | AD10: 45829 | AE10: 46011 | AF10: REGIONAL ANTIOQUIA | AG10: PRODUCTIVA | AH10: 800088702 | AI10: EPS SURA | AJ10: 830025999 | AK10: AGENCIA DE SEGUROS SALUD PLUS LTDA | AL10: 45832.522
A11: Carlos Negrete | B11: 890904996 | C11: EMPRESAS PUBLICAS DE MEDELLIN E.S.P. | D11: ANTIOQUIA | E11: MEDELLIN | F11: Cra. 58 42-125 | G11: 3805178 | H11: Lina.quintero@epm.com.co;maria.yubelli.bolivar@epm.com.co;dep01980552@epm.com.co | I11: C.C. | J11: 1001033198 | K11: ARANGO CABRERA | L11: JOHN ESTEBAN | M11: 36578 | N11: M | P11: 3225394920 | Q11: arangoe741@gmail.com | R11: 5 | S11: ANTIOQUIA | T11: 45 | U11: APARTADO | V11: 950400 | W11: COMPLEJO TECNOLOGICO AGROINDUSTRIAL,PECUARIO Y TURISTICO -URABA- | X11: TECNÓLOGO EN SUPERVISIÓN DE REDES DE DISTRIBUCIÓN DE ENERGÍA ELÉCTRICA | Y11: 2775376 | Z11: 45117 | AA11: 45757 | AB11: 45758 | AC11: 45939 | AD11: 45832 | AE11: 46012 | AF11: REGIONAL ANTIOQUIA | AG11: PRODUCTIVA | AH11: 900156264 | AI11: NUEVA EPS | AJ11: 860013816 | AK11: POSITIVA | AL11: 45834.641
A12: Dina Dorado | B12: 890929589 | C12: INVERSIONES GOMEZ JARAMILLO S.A.S. | D12: ANTIOQUIA | E12: MEDELLIN | F12: LKM4 VIA AEROPUERTO LOS CEDROS FINCA LAS PAMPAS | G12: 3174365306 | H12: info@ingajo.com | I12: C.C. | J12: 1027941264 | K12: GARCÉS VARGAS | L12: MARYORYS | M12: 38066 | N12: F | P12: 3175075734 | Q12: maryorisgarces49@gmail.com | R12: 5 | S12: ANTIOQUIA | T12: 837 | U12: TURBO | V12: 950400 | W12: COMPLEJO TECNOLOGICO AGROINDUSTRIAL,PECUARIO Y TURISTICO -URABA- | X12: TECNICO EN CULTIVOS AGRICOLAS | Y12: 2925489 | Z12: 45355 | AA12: 45630 | AB12: 45631 | AC12: 45811 | AD12: 45834 | AE12: 46014 | AF12: REGIONAL ANTIOQUIA | AG12: PRODUCTIVA | AH12: 800088702 | AI12: EPS SURA | AJ12: 860013816 | AK12: POSITIVA | AL12: 45834.345
A13: Yorger Moreno | B13: 901122707 | C13: HACIENDA SAN BARTOLO S.A.S. ZOMAC | D13: ANTIOQUIA | E13: MEDELLIN | F13: cra 43 a #1a sur -69 | G13: 2664112 | H13: asistentenomina@lahaciendasas.com.co | I13: C.C. | J13: 1037122141 | K13: ECHAVARRIA GALLEGO | L13: STEVEN ALEJANDRO | M13: 10/02/2007 | N13: M | P13: 82820072 | Q13: stivenechavarria019@gmail.com | R13: 5 | S13: ANTIOQUIA | T13: 172 | U13: CHIGORODO | V13: 950400 | W13: COMPLEJO TECNOLOGICO AGROINDUSTRIAL,PECUARIO Y TURISTICO -URABA- | X13: TECNÓLOGO EN GESTION AGROEMPRESARIAL | Y13: 2910664 | Z13: 20/02/2024 | AA13: 20/11/2025 | AB13: 21/11/2025 | AC13: 19/05/2026 | AD13: 22/09/2025 | AE13: 46014 | AF13: REGIONAL ANTIOQUIA | AG13: LECTIVA - PRODUCTIVA | AH13: 800088702 | AI13: EPS SURA | AJ13: 830025999 | AK13: AGENCIA DE SEGUROS SALUD PLUS LTDA | AL13: 45929.379 | AN13: EL APRENDIZ NO CUMPLE CON CONOCIMIENTOS BÁSICOS | AO13: Durante los días 21, 22 de noviembre 2025, 3, 5 y 9 de diciembre de 2025, usted ha dejado de presentarse a su centro de trabajo, sin permiso de su empleador y sin entregar soportes válidos
A14: Abel Valderrama | B14: 900124689 | C14: FUNDACION SOMA | D14: ANTIOQUIA | E14: CHIGORODO | F14: CR 106 CL 95 | G14: 3116095402 | H14: direccionadministrativa@fundacionsoma.com | I14: C.C. | J14: 1077996318 | K14: GUTIERREZ CORDOBA | L14: JHON DARWIN | M14: 06/06/2002 | N14: M | P14: 573138711513 | Q14: jhonsitogutierrez1@gmail.com | R14: 27 | S14: CHOCO | T14: 1 | U14: QUIBDO | V14: 950400 | W14: COMPLEJO TECNOLOGICO AGROINDUSTRIAL,PECUARIO Y TURISTICO -URABA- | X14: TÉCNICO EN SISTEMAS TELEINFORMÁTICOS | Y14: 3077813 | Z14: 16/09/2024 | AA14: 16/06/2025 | AB14: 17/06/2025 | AC14: 15/12/2025 | AD14: 28/06/2025 | AE14: 46018 | AF14: REGIONAL ANTIOQUIA | AG14: PRODUCTIVA | AH14: 901037916 | AI14: ADRES EPS | AJ14: 830025999 | AK14: AGENCIA DE SEGUROS SALUD PLUS LTDA | AL14: 45841.418
A15: Didier Zuñiga | B15: 800158328 | C15: CARDIOESTUDIO S.A.S. | D15: ANTIOQUIA | E15: MEDELLIN | F15: Calle 2 sur # 46 -78 Apt 201 | G15: 3117467687 | H15: luz.ortiz@cardioestudio.com | I15: C.C. | J15: 1001033567 | K15: GOMEZ PALACIO | L15: MARCELA | M15: 36740 | N15: F | P15: 3234788121 | Q15: gjohnjader@gmail.com | R15: 5 | S15: ANTIOQUIA | T15: 45 | U15: APARTADO | V15: 950400 | W15: COMPLEJO TECNOLOGICO AGROINDUSTRIAL,PECUARIO Y TURISTICO -URABA- | X15: TECNÓLOGO EN GESTION ADMINISTRATIVA DEL SECTOR SALUD. | Y15: 2826376 | Z15: 45201 | AA15: 45840 | AB15: 45841 | AC15: 46023 | AD15: 45782 | AE15: 46021 | AF15: REGIONAL ANTIOQUIA | AG15: LECTIVA - PRODUCTIVA | AH15: 800088702 | AI15: EPS SURA | AJ15: 800256161 | AK15: ARP SURA | AL15: 45782.662
A16: Lucy Pernett | B16: 98529410 | C16: SALAZAR VALLEJO JHON JAIRO | D16: ANTIOQUIA | E16: MEDELLIN | F16: cra 45 # 25-39 | G16: 3023589515 | H16: personalnaturalma@gmail.com | I16: T.I. | J16: 1073981403 | K16: FERNANDEZ CUESTA | L16: LUZ NEIDYS | M16: 39188 | N16: F | P16: 5748206463 | Q16: fluz9220@gmail.com | R16: 5 | S16: ANTIOQUIA | T16: 837 | U16: TURBO | V16: 950400 | W16: COMPLEJO TECNOLOGICO AGROINDUSTRIAL,PECUARIO Y TURISTICO -URABA- | X16: TÉCNICO EN SERVICIOS COMERCIALES Y FINANCIEROS | Y16: 2917215 | Z16: 45352 | AA16: 45627 | AB16: 45628 | AC16: 45808 | AD16: 45839 | AE16: 46021 | AF16: REGIONAL ANTIOQUIA | AG16: PRODUCTIVA | AH16: 800088702 | AI16: EPS SURA | AJ16: 860013816 | AK16: POSITIVA | AL16: 45839.593
A17: Maria del Rosari Jaramillo | B17: 890917555 | C17: COOPERATIVA DE EDUCACION DE URABA | D17: ANTIOQUIA | E17: APARTADO | F17: diagonal 105c | G17: 3153066884 | H17: administrativa@educoop.com.co | I17: C.C. | J17: 1007898878 | K17: FLOREZ PEREZ | L17: LILY YULIANA | M17: 37207 | N17: F | P17: 3102116857 | Q17: lilyyulianaflorezperez@gmail.com | R17: 5 | S17: ANTIOQUIA | T17: 45 | U17: APARTADO | V17: 950400 | W17: COMPLEJO TECNOLOGICO AGROINDUSTRIAL,PECUARIO Y TURISTICO -URABA- | X17: TECNICO EN ATENCION INTEGRAL A LA PRIMERA INFANCIA | Y17: 2878845 | Z17: 45313 | AA17: 45587 | AB17: 45588 | AC17: 45768 | AD17: 45839 | AE17: 46021 | AF17: REGIONAL ANTIOQUIA | AG17: PRODUCTIVA | AH17: 890900286 | AI17: SAVIA SALUD E.P.S. | AJ17: 860028415 | AK17: SEGUROS LA EQUIDAD | AL17: 45839.503
A18: Marcelino Gonzalez | B18: 800021137 | C18: AGRICOLA SARA PALMA S.A. | D18: ANTIOQUIA | E18: MEDELLIN | F18: apartado | G18: 3103531316 | H18: Gviera@sarapalma.com.co | I18: C.C. | J18: 1027947047 | K18: POLO CORDERO | L18: JUAN DAVID | M18: 15/02/2005 | N18: M | P18: 3237034237 | Q18: poloj2459@gmail.com | R18: 5 | S18: ANTIOQUIA | T18: 147 | U18: CAREPA | V18: 950400 | W18: COMPLEJO TECNOLOGICO AGROINDUSTRIAL,PECUARIO Y TURISTICO -URABA- | X18: TECNÓLOGO EN GESTION DE LA PRODUCCION AGRICOLA | Y18: 2826366 | Z18: 02/10/2023 | AA18: 02/07/2025 | AB18: 03/07/2025 | AC18: 31/12/2025 | AD18: 20/02/2024 | AE18: 46022 | AF18: REGIONAL ANTIOQUIA | AG18: LECTIVA - PRODUCTIVA | AH18: 900156264 | AI18: NUEVA EPS | AJ18: 800256161 | AK18: ARP SURA | AL18: 45350.369
A19: Marcelino Gonzalez | B19: 800021137 | C19: AGRICOLA SARA PALMA S.A. | D19: ANTIOQUIA | E19: MEDELLIN | F19: apartado | G19: 3103531316 | H19: Gviera@sarapalma.com.co | I19: C.C. | J19: 1037116279 | K19: ROMERO MADARIAGA | L19: SEIDY ALEJANDRA | M19: 08/05/2004 | N19: F | P19: 573045945012 | Q19: seidyalejandraromero@gmail.com | R19: 5 | S19: ANTIOQUIA | T19: 172 | U19: CHIGORODO | V19: 950400 | W19: COMPLEJO TECNOLOGICO AGROINDUSTRIAL,PECUARIO Y TURISTICO -URABA- | X19: TECNÓLOGO EN GESTION DE LA PRODUCCION AGRICOLA | Y19: 2826366 | Z19: 02/10/2023 | AA19: 02/07/2025 | AB19: 03/07/2025 | AC19: 31/12/2025 | AD19: 01/03/2024 | AE19: 46022 | AF19: REGIONAL ANTIOQUIA | AG19: LECTIVA - PRODUCTIVA | AH19: 900156264 | AI19: NUEVA EPS | AJ19: 800256161 | AK19: ARP SURA | AL19: 45358.469
A20: Marcelino Gonzalez | B20: 890917006 | C20: AGROPECUARIA YERBAZAL S.A. | D20: ANTIOQUIA | E20: MEDELLIN | F20: CRA77 N 33 A 83 | G20: 3104536401 | H20: SISO@YERBAZAL.CO | I20: C.C. | J20: 1001030517 | K20: SANCHEZ SANCHEZ | L20: SDRUAL ENRIQUE | M20: 22/02/2002 | N20: M | P20: 3017131013 | Q20: asdrual07897320730937@gmail.com | R20: 5 | S20: ANTIOQUIA | T20: 45 | U20: APARTADO | V20: 950400 | W20: COMPLEJO TECNOLOGICO AGROINDUSTRIAL,PECUARIO Y TURISTICO -URABA- | X20: TECNÓLOGO EN GESTION DE LA PRODUCCION AGRICOLA | Y20: 2826366 | Z20: 02/10/2023 | AA20: 02/07/2025 | AB20: 03/07/2025 | AC20: 31/12/2025 | AD20: 25/04/2024 | AE20: 46022 | AF20: REGIONAL ANTIOQUIA | AG20: LECTIVA - PRODUCTIVA | AH20: 900156264 | AI20: NUEVA EPS | AJ20: 860013816 | AK20: POSITIVA | AL20: 45408.308
A21: Marcelino Gonzalez | B21: 890941851 | C21: INVERSIONES UCRANIA SAS | D21: ANTIOQUIA | E21: MEDELLIN | F21: KM 5 VIA NUEVA COLONIA | G21: 3152537555 | H21: INVERUCRANIA@GUCRANIA.COM | I21: C.C. | J21: 1032176563 | K21: OSORIO PEREZ | L21: LUIS DAVID | M21: 08/08/2004 | N21: M | P21: 5713385374 | Q21: luisosoriop17@gmail.com | R21: 5 | S21: ANTIOQUIA | T21: 45 | U21: APARTADO | V21: 950400 | W21: COMPLEJO TECNOLOGICO AGROINDUSTRIAL,PECUARIO Y TURISTICO -URABA- | X21: TECNÓLOGO EN GESTION DE LA PRODUCCION AGRICOLA | Y21: 2826366 | Z21: 02/10/2023 | AA21: 02/07/2025 | AB21: 03/07/2025 | AC21: 31/12/2025 | AD21: 08/05/2024 | AE21: 46022 | AF21: REGIONAL ANTIOQUIA | AG21: LECTIVA - PRODUCTIVA | AH21: 900156264 | AI21: NUEVA EPS | AJ21: 860013816 | AK21: POSITIVA | AL21: 45420.54
A22: Marcelino Gonzalez | B22: 890101826 | C22: FINCA CIBELES S.A. | D22: ATLANTICO | E22: BARRANQUILLA | F22: CRR 113 N 105C-53 CASA 84 | G22: 8427297 | H22: tesoreria@fincacibeles.com | I22: C.C. | J22: 1001154371 | K22: CALLE COGOLLO | L22: DANIEL | M22: 08/12/2003 | N22: M | P22: 3216926772 | Q22: callejavier@yahoo.com | R22: 5 | S22: ANTIOQUIA | T22: 45 | U22: APARTADO | V22: 950400 | W22: COMPLEJO TECNOLOGICO AGROINDUSTRIAL,PECUARIO Y TURISTICO -URABA- | X22: TECNÓLOGO EN GESTION DE LA PRODUCCION AGRICOLA | Y22: 2826366 | Z22: 02/10/2023 | AA22: 02/07/2025 | AB22: 03/07/2025 | AC22: 31/12/2025 | AD22: 16/08/2024 | AE22: 46022 | AF22: REGIONAL ANTIOQUIA | AG22: LECTIVA - PRODUCTIVA | AH22: 800088702 | AI22: EPS SURA | AJ22: 860013816 | AK22: POSITIVA | AL22: 45532.448 | AN22: Terminación automática por fecha de contrato Automatic Job1
A23: Marcelino Gonzalez | B23: 900296617 | C23: AGRICOLA SAN RIOMAR S.A.S | D23: ANTIOQUIA | E23: APARTADO | F23: CARRERA 109 C NO. 100 - 15 EDIFICIO OCÉANO OFICINA 101 | G23: 3116473007 | H23: AGRICOLASANRIOMAR@HOTMAIL.COM | I23: C.C. | J23: 1040353438 | K23: JERONIMO SIERRA | L23: SANTIAGO | M23: 17/04/2005 | N23: M | P23: 6018285266 | Q23: santiagojeronimosierra@gmail.com | R23: 5 | S23: ANTIOQUIA | T23: 45 | U23: APARTADO | V23: 950400 | W23: COMPLEJO TECNOLOGICO AGROINDUSTRIAL,PECUARIO Y TURISTICO -URABA- | X23: TECNÓLOGO EN GESTION DE LA PRODUCCION AGRICOLA | Y23: 2826366 | Z23: 02/10/2023 | AA23: 02/07/2025 | AB23: 03/07/2025 | AC23: 31/12/2025 | AD23: 01/08/2024 | AE23: 46022 | AF23: REGIONAL ANTIOQUIA | AG23: PRODUCTIVA | AH23: 800088702 | AI23: EPS SURA | AJ23: 860013816 | AK23: POSITIVA | AL23: 45553.664
A24: Aldwin Morelo | B24: 901122707 | C24: HACIENDA SAN BARTOLO S.A.S. ZOMAC | D24: ANTIOQUIA | E24: MEDELLIN | F24: cra 43 a #1a sur -69 | G24: 2664112 | H24: asistentenomina@lahaciendasas.com.co | I24: C.C. | J24: 1038801870 | K24: GOMEZ VERGARA | L24: ANA ISABEL | M24: 38875 | N24: F | P24: 5748254907 | Q24: gomezanaisabel2023@gmail.com | R24: 5 | S24: ANTIOQUIA | T24: 172 | U24: CHIGORODO | V24: 950400 | W24: COMPLEJO TECNOLOGICO AGROINDUSTRIAL,PECUARIO Y TURISTICO -URABA- | X24: TECNICO EN CONSERVACION DE RECURSOS NATURALES | Y24: 3051477 | Z24: 45524 | AA24: 45797 | AB24: 45798 | AC24: 45980 | AD24: 45839 | AE24: 46022 | AF24: REGIONAL ANTIOQUIA | AG24: PRODUCTIVA | AH24: 890900286 | AI24: SAVIA SALUD E.P.S. | AJ24: 800256161 | AK24: ARP SURA | AL24: 45840.738
A25: Yolanda Berrío | B25: 899999034 | C25: SERVICIO NACIONAL DE APRENDIZAJE, SENA | D25: BOGOTA D.C. | E25: BOGOTA D. C. | F25: Carrera 9 71N-60 | G25: 3107056945 | H25: cavendanov@sena.edu.co | I25: C.C. | J25: 1027959844 | K25: GARCES CANO | L25: NALLIBE VIANELA | M25: 19/01/2007 | N25: F | P25: 573192197521 | Q25: nallibegarces0@gmail.com | R25: 5 | S25: ANTIOQUIA | T25: 172 | U25: CHIGORODO | V25: 950400 | W25: COMPLEJO TECNOLOGICO AGROINDUSTRIAL,PECUARIO Y TURISTICO -URABA- | X25: TECNICO EN SISTEMAS AGROPECUARIOS ECOLOGICOS. | Y25: 3004049 | Z25: 05/06/2024 | AA25: 14/04/2025 | AB25: 15/04/2025 | AC25: 13/10/2025 | AD25: 01/07/2025 | AE25: 46022 | AF25: REGIONAL ANTIOQUIA | AG25: PRODUCTIVA | AH25: 890900286 | AI25: SAVIA SALUD E.P.S. | AJ25: 860013816 | AK25: POSITIVA | AL25: 45841.681
A26: Silvia Chaverra | B26: 800197268 | C26: DIAN | D26: RISARALDA | E26: PEREIRA | F26: Cra. 7 # 6C - 54 - Piso 8° - Edifício Sendas | G26: 6017428973 | H26: mvegaa@dian.gov.co | I26: C.C. | J26: 1045524311 | K26: BLANDON GONZALEZ | L26: YARLENNY | M26: 18/11/1996 | N26: F | P26: 573106392117 | Q26: yarlennyblandon3@gmail.com | R26: 5 | S26: ANTIOQUIA | T26: 837 | U26: TURBO | V26: 950400 | W26: COMPLEJO TECNOLOGICO AGROINDUSTRIAL,PECUARIO Y TURISTICO -URABA- | X26: TÉCNICO EN CONTABILIZACION DE OPERACIONES COMERCIALES Y FINANCIERAS. | Y26: 2855479 | Z26: 02/10/2023 | AA26: 02/07/2024 | AB26: 03/07/2024 | AC26: 01/01/2025 | AD26: 03/07/2025 | AE26: 46022 | AF26: REGIONAL ANTIOQUIA | AG26: PRODUCTIVA | AH26: 800249241 | AI26: E.P.S. COOSALUD | AJ26: 860013816 | AK26: POSITIVA | AL26: 45848.655
A27: Yorger Moreno | B27: 900089324 | C27: AGRICOLA MAYORCA S.A. | D27: ANTIOQUIA | E27: MEDELLIN | F27: CARRERA 43A No. 19-17 EDIFICIO BLOCK EMPRESARIAL PISO 12 | G27: 4440009 - 8243483 (URABA) | H27: analistacontrataciones@banafrut.com | I27: C.C. | J27: 1037119314 | K27: BARON PAYARES | L27: ESTEBAN | M27: 38150 | N27: M | P27: 5748254907 | Q27: estevanbaron13@gmail.com | R27: 5 | S27: ANTIOQUIA | T27: 172 | U27: CHIGORODO | V27: 950400 | W27: COMPLEJO TECNOLOGICO AGROINDUSTRIAL,PECUARIO Y TURISTICO -URABA- | X27: TECNICO EN CONSERVACION DE RECURSOS NATURALES | Y27: 3051477 | Z27: 45524 | AA27: 45797 | AB27: 45798 | AC27: 45980 | AD27: 45840 | AE27: 46023 | AF27: REGIONAL ANTIOQUIA | AG27: PRODUCTIVA | AH27: 900156264 | AI27: NUEVA EPS | AJ27: 800256161 | AK27: ARP SURA | AL27: 45840.336
A28: Bernardo Brand | B28: 900296617 | C28: AGRICOLA SAN RIOMAR S.A.S | D28: ANTIOQUIA | E28: APARTADO | F28: CARRERA 109 C NO. 100 - 15 EDIFICIO OCÉANO OFICINA 101 | G28: 3116473007 | H28: AGRICOLASANRIOMAR@HOTMAIL.COM | I28: C.C. | J28: 1129684404 | K28: TORDECILLA PEÑA | L28: JAVIER ANTONIO | M28: 11/08/2006 | N28: M | P28: 3207428412 | Q28: javiertordecilla702@gmail.com | R28: 5 | S28: ANTIOQUIA | T28: 659 | U28: SAN JUAN DE URABA | V28: 950400 | W28: COMPLEJO TECNOLOGICO AGROINDUSTRIAL,PECUARIO Y TURISTICO -URABA- | X28: TECNICO EN PRODUCCION AGROPECUARIA | Y28: 3000012 | Z28: 22/05/2024 | AA28: 22/02/2025 | AB28: 23/02/2025 | AC28: 21/08/2025 | AD28: 03/07/2025 | AE28: 46024 | AF28: REGIONAL ANTIOQUIA | AG28: PRODUCTIVA | AH28: 900156264 | AI28: NUEVA EPS | AJ28: 860013816 | AK28: POSITIVA | AL28: 45841.521
A29: Bernardo Brand | B29: 900296617 | C29: AGRICOLA SAN RIOMAR S.A.S | D29: ANTIOQUIA | E29: APARTADO | F29: CARRERA 109 C NO. 100 - 15 EDIFICIO OCÉANO OFICINA 101 | G29: 3116473007 | H29: AGRICOLASANRIOMAR@HOTMAIL.COM | I29: C.C. | J29: 1037468930 | K29: ALTAMIRANDA VENERA | L29: ZARIHT JUDIHT | M29: 24/11/2004 | N29: F | P29: 3124753556 | Q29: zarithaltamiranda57@gmail.com | R29: 5 | S29: ANTIOQUIA | T29: 659 | U29: SAN JUAN DE URABA | V29: 950400 | W29: COMPLEJO TECNOLOGICO AGROINDUSTRIAL,PECUARIO Y TURISTICO -URABA- | X29: TECNICO EN PRODUCCION AGROPECUARIA | Y29: 3000012 | Z29: 22/05/2024 | AA29: 22/02/2025 | AB29: 23/02/2025 | AC29: 21/08/2025 | AD29: 07/07/2025 | AE29: 46028 | AF29: REGIONAL ANTIOQUIA | AG29: PRODUCTIVA | AH29: 890900286 | AI29: SAVIA SALUD E.P.S. | AJ29: 860013816 | AK29: POSITIVA | AL29: 45848.599
A30: Bernardo Brand | B30: 900296617 | C30: AGRICOLA SAN RIOMAR S.A.S | D30: ANTIOQUIA | E30: APARTADO | F30: CARRERA 109 C NO. 100 - 15 EDIFICIO OCÉANO OFICINA 101 | G30: 3116473007 | H30: AGRICOLASANRIOMAR@HOTMAIL.COM | I30: C.C. | J30: 1007834056 | K30: VILLA MARTINEZ | L30: MANUEL ESTEBAN | M30: 09/05/1996 | N30: M | P30: 573105602486 | Q30: villamartinezmanuelesteban@gmail.com | R30: 5 | S30: ANTIOQUIA | T30: 659 | U30: SAN JUAN DE URABA | V30: 950400 | W30: COMPLEJO TECNOLOGICO AGROINDUSTRIAL,PECUARIO Y TURISTICO -URABA- | X30: TECNICO EN PRODUCCION AGROPECUARIA | Y30: 3016710 | Z30: 15/06/2024 | AA30: 15/03/2025 | AB30: 16/03/2025 | AC30: 14/09/2025 | AD30: 07/07/2025 | AE30: 46028 | AF30: REGIONAL ANTIOQUIA | AG30: PRODUCTIVA | AH30: 890900286 | AI30: SAVIA SALUD E.P.S. | AJ30: 860013816 | AK30: POSITIVA | AL30: 45848.599
A31: Bernardo Brand | B31: 900296617 | C31: AGRICOLA SAN RIOMAR S.A.S | D31: ANTIOQUIA | E31: APARTADO | F31: CARRERA 109 C NO. 100 - 15 EDIFICIO OCÉANO OFICINA 101 | G31: 3116473007 | H31: AGRICOLASANRIOMAR@HOTMAIL.COM | I31: T.I. | J31: 1037471796 | K31: SANCHEZ VEGA | L31: YULISA JUDITH | M31: 19/11/2006 | N31: F | P31: 3192793876 | Q31: luiseduardoespitia11@gmail.com | R31: 5 | S31: ANTIOQUIA | T31: 659 | U31: SAN JUAN DE URABA | V31: 950400 | W31: COMPLEJO TECNOLOGICO AGROINDUSTRIAL,PECUARIO Y TURISTICO -URABA- | X31: TECNICO EN PRODUCCION AGROPECUARIA | Y31: 3016710 | Z31: 15/06/2024 | AA31: 15/03/2025 | AB31: 16/03/2025 | AC31: 14/09/2025 | AD31: 07/07/2025 | AE31: 46028 | AF31: REGIONAL ANTIOQUIA | AG31: PRODUCTIVA | AH31: 890900286 | AI31: SAVIA SALUD E.P.S. | AJ31: 860013816 | AK31: POSITIVA | AL31: 45849.745
A32: Carlos Negrete | B32: 900970799 | C32: + MOTOS + REPUESTOS S.A.S | D32: ANTIOQUIA | E32: MEDELLIN | F32: Cra 43 b 16 95 ofi 204 | G32: 300 3519957 | H32: seleccion@masmotos.com.co | I32: C.C. | J32: 1233692934 | K32: CASTRO DURANGO | L32: EDUARD ARLEY | M32: 29/11/1998 | N32: M | P32: 573163178679 | Q32: castrodurangoeduardarley@gmail.com | R32: 5 | S32: ANTIOQUIA | T32: 172 | U32: CHIGORODO | V32: 950400 | W32: COMPLEJO TECNOLOGICO AGROINDUSTRIAL,PECUARIO Y TURISTICO -URABA- | X32: TÉCNICO EN MANTENIMIENTO DE MOTOCICLETAS Y MOTOCARROS. | Y32: 2937357 | Z32: 08/03/2024 | AA32: 08/12/2024 | AB32: 09/12/2024 | AC32: 06/06/2025 | AD32: 10/07/2025 | AE32: 46031 | AF32: REGIONAL ANTIOQUIA | AG32: PRODUCTIVA | AH32: 890900286 | AI32: SAVIA SALUD E.P.S. | AJ32: 800256161 | AK32: ARP SURA | AL32: 45848.674
A33: Abel Valderrama | B33: 900340993 | C33: ADMINISTRACION DE REDES Y PROYECTOS S A S | D33: BOGOTA D.C. | E33: BOGOTA D. C. | F33: Calle 26 No. 102 - 30 Piso 3 Oficina 303 | G33: 6533909 Ext 829 | H33: adredsas@gmail.com | I33: C.C. | J33: 1027959243 | K33: HERNANDEZ MONTES | L33: KAROL JULIANA | M33: 04/07/2005 | N33: F | P33: 3052789949 | Q33: Karoljulianahernandezmontes04@gmail.com | R33: 5 | S33: ANTIOQUIA | T33: 45 | U33: APARTADO | V33: 950400 | W33: COMPLEJO TECNOLOGICO AGROINDUSTRIAL,PECUARIO Y TURISTICO -URABA- | X33: TECNÓLOGO EN IMPLEMENTACION DE INFRAESTRUCTURA DE TECNOLOGIAS DE LA INFORMACION Y LAS COMUNICACIONES | Y33: 2693983 | Z33: 02/02/2023 | AA33: 02/11/2024 | AB33: 03/11/2024 | AC33: 01/05/2025 | AD33: 11/07/2025 | AE33: 46032 | AF33: REGIONAL ANTIOQUIA | AG33: PRODUCTIVA | AH33: 890900286 | AI33: SAVIA SALUD E.P.S. | AJ33: 800256161 | AK33: ARP SURA | AL33: 45849.35
A34: Silvia Chaverra | B34: 900072303 | C34: AGUAS REGIONALES EPM S.A. E.S.P. | D34: ANTIOQUIA | E34: APARTADO | F34: CALLE 97 A NO. 104 - 13 | G34: 8286657 | H34: ESTEBAN.MADERA@aguasregionales.com;maria.torres@aguasregionales.com | I34: C.C. | J34: 1045491428 | K34: VILLEGAS CORDOBBA | L34: JHON FREDY | M34: 09/01/2005 | N34: M | P34: 573015100130 | Q34: jhonfredisvillegascordoba@gmail.com | R34: 5 | S34: ANTIOQUIA | T34: 837 | U34: TURBO | V34: 950400 | W34: COMPLEJO TECNOLOGICO AGROINDUSTRIAL,PECUARIO Y TURISTICO -URABA- | X34: TÉCNICO EN SERVICIOS COMERCIALES Y FINANCIEROS | Y34: 2995116 | Z34: 04/06/2024 | AA34: 04/03/2025 | AB34: 05/03/2025 | AC34: 03/09/2025 | AD34: 14/07/2025 | AE34: 46035 | AF34: REGIONAL ANTIOQUIA | AG34: PRODUCTIVA | AH34: 891600091 | AI34: EPS COMFACHOCO | AJ34: 800226175 | AK34: COLMENA RIESGOS PROFESIONALES | AL34: 45853.315
A35: Yorger Moreno | B35: 70073635 | C35: SIERRA MORENO RUBEN DARIO | D35: ANTIOQUIA | E35: MEDELLIN | F35: calle 4 sur 43a 195 of 214 | G35: 3128512474 | H35: hdanotecanses@hotmail.com | I35: C.C. | J35: 1037122067 | K35: VILLA URREGO | L35: DILAL ESTENIO | M35: 25/01/2007 | N35: M | P35: 3106371213 | Q35: villadilal44@gmail.com | R35: 5 | S35: ANTIOQUIA | T35: 172 | U35: CHIGORODO | V35: 950400 | W35: COMPLEJO TECNOLOGICO AGROINDUSTRIAL,PECUARIO Y TURISTICO -URABA- | X35: TECNÓLOGO EN GESTION AGROEMPRESARIAL | Y35: 2910664 | Z35: 20/02/2024 | AA35: 20/11/2025 | AB35: 21/11/2025 | AC35: 19/05/2026 | AD35: 13/11/2024 | AE35: 46035 | AF35: REGIONAL ANTIOQUIA | AG35: LECTIVA - PRODUCTIVA | AH35: 890900286 | AI35: SAVIA SALUD E.P.S. | AJ35: 999999999 | AK35: No registrada | AL35: 45609.378 | AN35: MUTUO ACUERDO(debe tener aprobación de la institución de formación)
A36: Aldwin Morelo | B36: 900021323 | C36: UNLAB S.A.S | D36: ANTIOQUIA | E36: APARTADO | F36: CARRERA 104 N 98 A - 03 | G36: 8156090 | H36: auxiliargh@unlab.co | I36: C.C. | J36: 1032178318 | K36: SERNA GARCIA | L36: EDWIN FELIPE | M36: 03/03/2006 | N36: M | P36: 3106317136 | Q36: edwinserna408@gmail.com | R36: 5 | S36: ANTIOQUIA | T36: 45 | U36: APARTADO | V36: 950400 | W36: COMPLEJO TECNOLOGICO AGROINDUSTRIAL,PECUARIO Y TURISTICO -URABA- | X36: TECNÓLOGO EN GESTION DE TESORERIA Y RECURSOS FINANCIEROS | Y36: 2826382 | Z36: 02/10/2023 | AA36: 02/07/2025 | AB36: 03/07/2025 | AC36: 31/12/2025 | AD36: 23/07/2025 | AE36: 46040 | AF36: REGIONAL ANTIOQUIA | AG36: PRODUCTIVA | AH36: 900156264 | AI36: NUEVA EPS | AJ36: 800226175 | AK36: COLMENA RIESGOS PROFESIONALES | AL36: 45861.49
A37: Abel Valderrama | B37: 900124689 | C37: FUNDACION SOMA | D37: ANTIOQUIA | E37: CHIGORODO | F37: CR 106 CL 95 | G37: 3116095402 | H37: direccionadministrativa@fundacionsoma.com | I37: C.C. | J37: 1027954769 | K37: DE LA CRUZ CONTRERAS | L37: JIMENA | M37: 05/05/2006 | N37: F | P37: 573017997826 | Q37: jimenacontreras082@gmail.com | R37: 5 | S37: ANTIOQUIA | T37: 147 | U37: CAREPA | V37: 950400 | W37: COMPLEJO TECNOLOGICO AGROINDUSTRIAL,PECUARIO Y TURISTICO -URABA- | X37: TÉCNICO EN SISTEMAS TELEINFORMÁTICOS | Y37: 3077813 | Z37: 16/09/2024 | AA37: 16/06/2025 | AB37: 17/06/2025 | AC37: 15/12/2025 | AD37: 22/07/2025 | AE37: 46043 | AF37: REGIONAL ANTIOQUIA | AG37: PRODUCTIVA | AH37: 901037916 | AI37: ADRES EPS | AJ37: 830025999 | AK37: AGENCIA DE SEGUROS SALUD PLUS LTDA | AL37: 45863.407
A38: Daisy Quejada | B38: 900929172 | C38: ELECTRODOMESTICOS J2 S.A.S. | D38: ANTIOQUIA | E38: SABANETA | F38: CARRERA 44 NO. 67SUR 28 | G38: 6044796767 | H38: claudia.londono@hdaelparaiso.com | I38: C.C. | J38: 1046527657 | K38: TOBON RUBIO | L38: SANTIAGO ANDRES | M38: 07/03/2006 | N38: M | P38: 5743104588 | Q38: santitobon71@gmail.com | R38: 5 | S38: ANTIOQUIA | T38: 837 | U38: TURBO | V38: 950400 | W38: COMPLEJO TECNOLOGICO AGROINDUSTRIAL,PECUARIO Y TURISTICO -URABA- | X38: TECNOLOGO EN GESTION ADMINISTRATIVA | Y38: 2901823 | Z38: 23/01/2024 | AA38: 23/07/2025 | AB38: 24/07/2025 | AC38: 22/01/2026 | AD38: 25/06/2024 | AE38: 46044 | AF38: REGIONAL ANTIOQUIA | AG38: LECTIVA - PRODUCTIVA | AH38: 900156264 | AI38: NUEVA EPS | AJ38: 860013816 | AK38: POSITIVA | AL38: 45468.615
A39: Daisy Quejada | B39: 800131731 | C39: FUNDACIÓN EDUCATIVA ISAIAS DUARTE CANCINO | D39: ANTIOQUIA | E39: APARTADO | F39: Cl 100 #94A - 109 - La chinita | G39: 3015151887 | H39: auxiliarth@diocesisdeapartado.org | I39: T.I. | J39: 1046528287 | K39: MENDOZA RODRIGUEZ | L39: DILANN ALEJANDRO | M39: 28/12/2006 | N39: M | P39: +57 323 4871713 | Q39: dilannmendoza3@gmail.com | R39: 5 | S39: ANTIOQUIA | T39: 837 | U39: TURBO | V39: 950400 | W39: COMPLEJO TECNOLOGICO AGROINDUSTRIAL,PECUARIO Y TURISTICO -URABA- | X39: TECNOLOGO EN GESTION ADMINISTRATIVA | Y39: 2901823 | Z39: 23/01/2024 | AA39: 23/07/2025 | AB39: 24/07/2025 | AC39: 22/01/2026 | AD39: 24/07/2025 | AE39: 46044 | AF39: REGIONAL ANTIOQUIA | AG39: PRODUCTIVA | AH39: 800088702 | AI39: EPS SURA | AJ39: 800256161 | AK39: ARP SURA | AL39: 45866.582
A40: Andrés Felipe Henao | B40: 901331695 | C40: MONTELLANA INGENIERIAS S.A.S | D40: ANTIOQUIA | E40: APARTADO | F40: BAJO DEL OSO SECTOR FINCA LA PRIMAVERA | G40: 3108268453 | H40: MONTELLANAINGENIERIASAS@GMAIL.COM | I40: C.C. | J40: 1027954226 | K40: RAMIREZ ARGEL | L40: DIEGO ALEJANDRO | M40: 18/03/2006 | N40: M | P40: 3117253668 | Q40: diegoalejandroargelramirez@gmail.com | R40: 5 | S40: ANTIOQUIA | T40: 45 | U40: APARTADO | V40: 950400 | W40: COMPLEJO TECNOLOGICO AGROINDUSTRIAL,PECUARIO Y TURISTICO -URABA- | X40: TÉCNICO EN MECANICA DE MAQUINARIA INDUSTRIAL | Y40: 3004048 | Z40: 06/06/2024 | AA40: 06/03/2025 | AB40: 07/03/2025 | AC40: 05/09/2025 | AD40: 24/07/2025 | AE40: 46045 | AF40: REGIONAL ANTIOQUIA | AG40: PRODUCTIVA | AH40: 800088702 | AI40: EPS SURA | AJ40: 800256161 | AK40: ARP SURA | AL40: 45862.35
...

Sheet Diferente a contrato
A1: ASIGNACIÓN DE INSTRUCTOR DE SEGUIMIENTO A APRENDICES CON ETAPA PRÁCTICA REGISTRADA DIFERENTE DE CONTRATO DE APRENDIZAJE | C1: ISABELA
A3: INSTRUCTOR SEGUIMIENTO | B3: ALTERNATIVA | C3: CORREO ELECTRONICO APRENDIZ | D3: TIPO DE DOCUMENTO | E3: NUMERO DE DOCUMENTO | F3: PRIMER APELLIDO | G3: SEGUNDO APELLIDO | H3: NOMBRES | I3: NOMBRE APRENDIZ | J3: SEXO (M ó F) | K3: DEPARTAMENTO RESIDENCIA | L3: MUNICIPIO RESIDENCIA | M3: DIRECCION RESIDENCIA APRENDIZ | N3: CELULAR O TELÉFONO FIJO | O3: EPS APRENDIZ | P3: FICHA | Q3: NOMBRE PROGRAMA | R3: MODALIDAD | S3: FECHA INICIO ETAPA PRODUCTIVA | T3: FECHA FIN ETAPA PRODUCTIVA | U3: NOMBRE DE LA EMPRESA | V3: DIRECCIÓN DE LA EMPRESA | W3: CIUDAD O MUNICIPIO | X3: CORREO ELECTRONICO EMPRESA | Y3: RESPONSABLE APRENDIZ | Z3: CELULAR O TELÉFOO FIJO
A4: Virtual | B4: Pasantía | C4: YUGOBU18@HOTMAIL.COM | D4: cc | E4: 1047417092 | F4: GOMEZ | G4: BURGOS | H4: YURLEIDIS | I4: Yurleidis Gomez Burgos | J4: F | K4: BOLÍVAR | L4: APARTADÓ | M4: BARRIO SANTANDER | N4: 3145818737 | O4: MUTUAL SER | P4: 2977539 | Q4: ATENCION INTEGRAL AL CLIENTE | R4: VIRTUAL | S4: 0 | T4: 0 | U4: ESE HOSPITAL LOCAL MAHATES | V4: BARRIO CENTELLA CALLE 1 N° 42-124 | W4: MAHATES | X4: HLMAHATES@OUTLOOK.COM | Y4: ROSANA MEDINA PEREZ | Z4: 3205446997
A5: Virtual | B5: Pasantía | C5: juanpablo08d@yahoo.es | D5: CC | E5: 74083718 | F5: ROA | G5: MONTAÑEZ | H5: JUAN PABLO | I5: Juan Pablo Roa Montañez | J5: M | K5: BOYACÁ | L5: APARTADÓ | M5: Calle 2 # 7 - 93 | N5: 3115652438 | O5: SANITAS | P5: 2834805 | Q5: ANALISIS Y DESARROLLO DE SOFTWARE. | R5: VIRTUAL | S5: 0 | T5: 0 | U5: REWDEV SAS | V5: Cr 73 57 R 15 sur | W5: BOGOTÁ | X5: management.rewdev@gmail.com | Y5: HAROLD DUQUE CASTAÑEDA | Z5: 3193342993
A6: Virtual | B6: Vinc. Lab. | C6: isalu1983@hotmail.com | D6: CC | E6: 30668995 | F6: CABRERA | G6: DE HOYOS | H6: YURIS PAOLA | I6: Yuris Paola Cabrera De Hoyos | J6: F | K6: ANTIOQUIA | L6: APARTADÓ | M6: CR 99C # 48B - 40 | N6: 3103507849 | O6: Sura | P6: 3185840 | Q6: ATENCION INTEGRAL AL CLIENTE | R6: VIRTUAL | S6: 0 | T6: 0 | U6: Colombia Móvil S.A. E.S.P | V6: Crra 50 # 96-12 | W6: BOGOTA | X6: adm.personal@tigo.com.co | Y6: SAIDA BENITEZ ARRIETA | Z6: 6046251505
A7: Carlos Negrete | B7: Pasantía | C7: neyrubiodavid@gmail.com | D7: cc | E7: 1028030695 | F7: RUBIO | G7: DAVID | H7: YISNEY | I7: Yisney Rubio David | J7: F | K7: ANTIOQUIA | L7: APARTADÓ | M7: calle 104D Carrera 96B | N7: 3106534305 | O7: Savia | P7: 2775376 | Q7: SUPERVISIÓN DE REDES DE DISTRIBUCIÓN DE ENERGÍA ELÉCTRICA | R7: PRESENCIAL | S7: 0 | T7: 0 | U7: STANDARD CONNECTION SAS | V7: CALLE 49B #99B-115 INTERIOR 205 | W7: MEDELLIN | X7: standardconnectionsas@gmail.com | Y7: Nacira Jimenez | Z7: 3126421889
A8: Virtual | B8: Vinc. Lab. | C8: juanmedina0718@gmail.com | D8: CC | E8: 1017181818 | F8: MEDINA | G8: VALENCIA | H8: JUAN CAMILO | I8: Juan Camilo Medina Valencia | J8: M | K8: VALLE DEL CAUCA | L8: CALI | M8: CR 46A # 43-79 | N8: 3214563431 | O8: NUEVA EPS | P8: 3069862 | Q8: ATENCION INTEGRAL AL CLIENTE | R8: VIRTUAL | S8: 16/09/2024 | T8: 45753 | U8: vinilos y estucos del valle | V8: Cra. 8 #72b-12 | W8: valle del cauca | X8: marketingdigital@vinilosyestucos.com | Y8: Edwin Moreno | Z8: 3122907680
A9: Silvia Chaverra | B9: Pasantía | C9: tatiibernal1998@gmail.com | D9: CC | E9: 1028035150 | F9: BERNAL | G9: TERAN | H9: INGRID TATIANA | I9: Ingrid Tatiana Bernal Teran | J9: F | K9: ANTIOQUIA | L9: APARTADO | M9: BARRIO OBRERO, BLOQUE 4 MANZANA 43 CASA 19 | N9: 3003269959 | O9: SURA | P9: 3013096 | Q9: SERVICIOS COMERCIALES Y FINANCIEROS | R9: PRESENCIAL | S9: 45839 | T9: 45992 | U9: PROMOTORA HOTELES URABA S.A.S | V9: CRA 100 # 88-21 EDIFICIO SANTA MARIA | W9: APARTADO | X9: JUAN.PALENCIA@ACCOR.COM | Y9: JUAN PALENCIA | Z9: 3205449784
A10: Lucy Pernett | B10: Vinc. Lab. | C10: daypa.delacruz@accor.com | D10: CC | E10: 1001033146 | F10: PALACIOS | G10: DE LA CRUZ | H10: DAYANA | I10: =PROPER(H10&" "&F10&" "&G10) -> Dayana Palacios De La Cruz | J10: F | K10: ANTIOQUIA | L10: APARTADÓ | M10: CIUDADELA COMFAMA | N10: 3145518402 | O10: NUEVA EPS | P10: 2924204 | Q10: COORDINACION DE SERVICIOS HOTELEROS | R10: PRESENCIAL | S10: 45817 | T10: 46000 | U10: PROMOTERA HOTELES URABA SAS | V10: CRA 100 # 88 21 | W10: APARTADO | X10: JUAN.PALENCIA@ACCOR.COM | Y10: JUAN DIEGO PALENCIA CORREA | Z10: 3205449784
A11: Maria del Rosari Jaramillo | B11: Pasantía | C11: acostagarcianinijhoana0@gmail.com | D11: CC | E11: 1007131264 | F11: ACOSTA | G11: GARCIA | H11: NINY JOHANA | I11: Niny Johana Acosta Garcia | J11: F | K11: ANTIOQUIA | L11: TURBO | M11: BARRIO 7 DE AGOSTO | N11: 323 482 02 52 | O11: SURA | P11: 3026343 | Q11: .ATENCION INTEGRAL A LA PRIMERA INFANCIA | R11: PRESENCIAL | S11: 45839 | T11: 46021 | U11: FUNDACIÓN DIOCESANA COMPARTIR | V11: BARRIO CHINITA, CARRERA 98 # 100 - 51 | W11: APARTADÓ ANTIOQUIA | X11: compartisedeturbo@gmailcom | Y11: DIANA TIRADO HERNANDEZ | Z11: 3148943614
A12: Abel Valderrama | B12: Pasantía | C12: valenciadarcln@gmail.com | D12: CC | E12: 1193313407 | F12: VALENCIA | G12: TANICAMA | H12: DARCILIANO | I12: Darciliano Valencia Tanicama | J12: M | K12: Antioquia | L12: Vigia del fuerte | M12: BarrioVenezuela | N12: 3226222247 | O12: Nueva eps | P12: 3001943 | Q12: SISTEMAS TELEINFORMÁTICOS | R12: PRESENCIAL | S12: 45840 | T12: 46022 | U12: I. E Rural Indigenista Embera Atrato Medio-Calle 3 #21-96 | V12: Cra 3 #21-96 Barrio Venezuela | W12: Vigía del Fuerte | X12: luzelenaalzatee960@gmail.com | Y12: Luz Elena Alzate Elejalde | Z12: 3173802004
A13: Virtual | B13: Vinc. Lab. | C13: leidylucas2007@gmail.com | D13: CC | E13: 1050958672 | F13: LUCAS | G13: BALTAZAR | H13: LEIDY PAOLA | I13: Leidy Paola Lucas Baltazar | J13: F | K13: BOLÍVAR | L13: APARTADÓ | M13: URB VILLA SANTA CATALINA | N13: 3106724940 | O13: SALUD TOTAL | P13: 3185840 | Q13: ATENCION INTEGRAL AL CLIENTE | R13: VIRTUAL | S13: 45751 | T13: 46023 | U13: MUNICIPIO DE MAHATES | V13: EDIFICIO PALACIO MUNICIPAL, K 37 NO 18-05 | W13: MAHATES | X13: educacion@mahates-bolivar.gov.co | Y13: Gustavo Junior Beleño Llerena | Z13: 3215669944
A14: Abel Valderrama | B14: Pasantía | C14: carmenjimenez.cjm53@gmail.com | D14: CC | E14: 1007131776 | F14: JIMENEZ | G14: MUENTES | H14: CARMEN MARIA | I14: Carmen Maria Jimenez Muentes | J14: F | K14: Antioquia | L14: Turbo | M14: 29 de noviembre nueva colonia | N14: 3135648805 | O14: SURA | P14: 2842920 | Q14: SISTEMAS. | R14: PRESENCIAL | S14: 45667 | T14: 46026 | U14: Municipio de Turbo | V14: Casa de Gobierno, Corr. Nva colonia | W14: Turbo | X14: casadegobiernonvacolonia@turbo-antioquia.gov.co | Y14: Guillermo Lopez Montaño | Z14: 3104300447
A15: Maria del Rosari Jaramillo | B15: Pasantía | C15: sandrasiso1992@gmail.com | D15: CC | E15: 1045511987 | F15: BARCOS | G15: PINEDA | H15: SANDRA YINESA | I15: Sandra Yinesa Barcos Pineda | J15: F | K15: Antioquia | L15: Turbo | M15: Barrio Invasion(Bosque) Cll.86 - Crr.21 | N15: 3103685499 | O15: Savia salud | P15: 2861388 | Q15: .ATENCION INTEGRAL A LA PRIMERA INFANCIA | R15: PRESENCIAL | S15: 45845 | T15: 46029 | U15: Centro Educativo Jardin Infantil Aqualuna. | V15: Barrio- Las delicias Calle99 Detrás de la Bombonera. | W15: Turbo Antioquia. | X15: AlejandraOviedo29@gmail.com | Y15: Alejandra Castro Oviedo. | Z15: 3232108949
A16: Abel Valderrama | B16: Pasantía | C16: samuelmonterrosagonzalez@gmail.com | D16: TI | E16: 1067897605 | F16: MONTERROSA | G16: GONZALEZ | H16: SAMUEL | I16: =PROPER(H16&" "&F16&" "&G16) -> Samuel Monterrosa Gonzalez | J16: M | K16: ANTIOQUIA | L16: ARBOLETTES | M16: B/VILLA LUZ | N16: 3218299276 | O16: SURAMERICANA S.A.-CM | P16: 2877398 | Q16: PROGRAMACION DE SOFTWARE . | R16: PRESENCIAL | S16: 45852 | T16: 46035 | U16: CONCEJO MUNICIPAL | V16: CALLE 31N°29-08. | W16: ARBOLETES | X16: Concejo@arboletes-antioquia.gov.co | Y16: ISABEL CRISTINA SUAREZ BAUTISTA | Z16: 320 6362948
A17: Julian Moreno | B17: Pasantía | C17: adrianvertel2007@gmail.com | D17: CC | E17: 1039087574 | F17: CAMPO | G17: VERTEL | H17: ADRIAN | I17: Adrian Campo Vertel | J17: M | K17: ANTIOQUIA | L17: NECOCLI | M17: Cra 45 #49-109 | N17: 3206843156 | O17: NUEVA EPS S.A. | P17: 2923976 | Q17: SERVICIOS FARMACEUTICOS | R17: PRESENCIAL | S17: 45853 | T17: 46037 | U17: ESE HOSPITAL SAN SEBASTIAN NECOCLI | V17: Km 1 vía Necoclí - Turbo | W17: Necoclí | X17: dmhospitalnecocli@gmail.com | Y17: Aris Cecilia Ayala | Z17: 3206625066
A18: Julian Moreno | B18: Pasantía | C18: zinedinequintero1@gmail.com | D18: CC | E18: 1075090276 | F18: QUINTERO | G18: TAPIA | H18: ZINEDINE | I18: Zinedine Quintero Tapia | J18: M | K18: ANTIOQUIA | L18: NECOCLI | M18: Calle 50 #47-13 | N18: 3207853833 | O18: SAVIA SALUD | P18: 2923976 | Q18: SERVICIOS FARMACEUTICOS | R18: PRESENCIAL | S18: 45853 | T18: 46037 | U18: ESE HOSPITAL SAN SEBASTIAN NECOCLI | V18: Km 1 vía Necoclí - Turbo | W18: Necoclí | X18: basiliagonzalez@hospitalnecocli.gov.co | Y18: Basilia Medrano González | Z18: 3146797001
A19: Julian Moreno | B19: Pasantía | C19: elianaisabelg543@gmail.com | D19: CC | E19: 1039083990 | F19: GUTIERREZ | G19: RODRIGUEZ | H19: ELIANA ISABEL | I19: Eliana Isabel Gutierrez Rodriguez | J19: F | K19: ANTIOQUIA | L19: NECOCLI | M19: Corregiiento El Mellito | N19: 3234201738 | O19: COOSALUD | P19: 2923976 | Q19: SERVICIOS FARMACEUTICOS | R19: PRESENCIAL | S19: 45853 | T19: 46037 | U19: ESE HOSPITAL SAN SEBASTIAN NECOCLI | V19: Km 1 vía Necoclí - Turbo | W19: Necoclí | X19: patriciaranzetac@hotmail.com | Y19: Erika Patricia Araanzeta Celis | Z19: 3105912589
A20: Maria del Rosari Jaramillo | B20: Pasantía | C20: VEPALACIOS6@MISENA.EDU.CO | D20: CC | E20: 1037120756 | F20: PALACIOS | G20: GUZMAN | H20: VANESSA EDITH | I20: Vanessa Edith Palacios Guzman | J20: F | K20: ANTIOQUIA | L20: CHIGORODO | M20: VEREDA LA BENDICIONES | N20: 3218179434 | O20: NUEVA EPS | P20: 2861415 | Q20: .ATENCION INTEGRAL A LA PRIMERA INFANCIA | R20: PRESENCIAL | S20: 15/07/2025 | T20: 46037 | U20: CORPORACION SILOH - OASIS DE ESPERANZA | V20: CLLE 84 #98-29 B/ El bosque | W20: CHIGORODO | X20: cdi282uraba@gamil.com | Y20: Edilma Contreras | Z20: 3108596574
A21: Abel Valderrama | B21: Pasantía | C21: danpingue@gmail.com | D21: CC | E21: 1067865573 | F21: PINEDA | G21: GUEVARA | H21: DANIEL | I21: Daniel Pineda Guevara | J21: M | K21: ANTIOQUIA | L21: ARBOLETTES | M21: B/DEPORTIVO | N21: 312 8994788 | O21: SAVIA SALUD | P21: 2877398 | Q21: PROGRAMACION DE SOFTWARE . | R21: PRESENCIAL | S21: 45858 | T21: 46042 | U21: SECRETARIA DE VICTIMAS | V21: CALLE 31N°29-08. | W21: ARBOLETES | X21: victimasarboletes2025@gmail.com | Y21: Lina Marcela Montalvo Ballesteros | Z21: 313 3336671
A22: Yerlis Hernández | B22: Pasantía | C22: veronicasibajaespitia@gmail.com | D22: CC | E22: 1041255369 | F22: SIBAJA | G22: ESPITIA | H22: VERONICA | I22: Veronica Sibaja Espitia | J22: F | K22: ANTIOQUIA | L22: SAN PEDRO DE URABÁ | N22: 3188100932 | O22: SAVIA SALUD | P22: 2775399 | Q22: EJECUCION DE PROGRAMAS DEPORTIVOS. | R22: PRESENCIAL | S22: 45862 | T22: 46046 | U22: ALCALDIA MUNICIPAL | W22: SAN PEDRO | X22: spedrouraba@indeportesantioquia.gov.co | Y22: JOSIMAR ANDRADES ESPITIA | Z22: 3044371446
A23: Yerlis Hernández | B23: Pasantía | C23: joseguramar04@gmail.com | D23: CC | E23: 1041260208 | F23: SEGURA | G23: MARTINEZ | H23: JOSE JOSE | I23: Jose Jose Segura Martinez | J23: M | K23: Antioquia | L23: San Pedro de Uraba | M23: B/ Brisas de uraba | N23: 3147684100 - 3113482723 | O23: Savia Salud | P23: 2775399 | Q23: EJECUCION DE PROGRAMAS DEPORTIVOS. | R23: PRESENCIAL | S23: 45839 | T23: 46052 | U23: Alcaldia Municipal - Educacion | V23: 50N° 52-114 B/ El centroo | W23: San Pedro de Uraba | X23: educacion@sanpedrodeuraba-antioquia.gov.co - gobierno@sanpedrodeuraba-antioquia.gov.co | Y23: Gilmor Murillo Murillo | Z23: 8205502 - ex 101 - 3017240730
A24: Nelvis Margoth Barboza Rivera | B24: Pasantía | C24: hernandezcarolinaj1229@gmail.com | D24: CC | E24: 1028002146 | F24: HERNANDEZ | G24: TABORDA | H24: YENI CAROLINA | I24: =PROPER(H24&" "&F24&" "&G24) -> Yeni Carolina Hernandez Taborda | J24: F | K24: ANTIOQUIA | L24: APARTADÓ | M24: CRR 79 B #103-04 | N24: 3137344026 | O24: NUEVA EPS | P24: 3031879 | Q24: SERVICIOS FARMACEUTICOS | R24: PRESENCIAL | S24: 45870 | T24: 46053 | U24: INVERSIONES PROGRESO ECHEVERRI ZOMAC SAS | V24: CRR 101 #95-16 BRR EL AMPARO | W24: APARTADÓ | X24: AUX.CONTABILIDAD@DROGUERIACOMERCIAL.COM | Y24: LUIS GUILLERMO GARCIA | Z24: 3104136592
A25: Yerlis Hernández | B25: Proy. Prod. | C25: j.leonardo10vegas.g@gmail.com | D25: CC | E25: 1127580804 | F25: VEGAS | G25: GONZALEZ | H25: JOSE LEONARDO | I25: Jose Leonardo Vegas Gonzalez | J25: M | K25: ANTIOQUIA | L25: ARBOLETES | M25: BARRIO ACEVEDO | N25: 3007766388 | O25: SAVIA SALUD | P25: 2945489 | Q25: EJECUCION DE PROGRAMAS DEPORTIVOS. | R25: PRESENCIAL | S25: 45299 | T25: 46055
A26: Virtual | B26: Pasantía | C26: karolgomez171@gmail.com | D26: CC | E26: 1000464538 | F26: CHAPARRO | G26: GOMEZ | H26: KAROL JULIANA | I26: Karol Juliana Chaparro Gomez | J26: F | K26: BOGOTÁ D.C. | L26: APARTADÓ | M26: Cra 100a # 135 - 09 | N26: 3013780475 | O26: Compensar | P26: 2834804 | Q26: ANALISIS Y DESARROLLO DE SOFTWARE. | R26: VIRTUAL | S26: 46024 | T26: 46060 | U26: Atomcol S.A.S | V26: Cra. 86 # 146-61 Bloque | W26: Bogota D.C | X26: dirfinanciero@atomcol.com | Y26: Jesus Perea | Z26: +(57)3163839949
A27: Carlos Negrete | B27: Pasantía | C27: shenao812@gmail.com | D27: CC | E27: 1027956691 | F27: HENAO | G27: PULGARIN | H27: JUAN SEBASTIAN | I27: Juan Sebastian Henao Pulgarin | J27: M | K27: ANTIOQUIA | L27: TURBO | M27: B/ LAS FLORES - CURRULAO | N27: 313 720 49 51 | O27: SAVIA SALUD | P27: 2998492 | Q27: INSTALACION Y MANTENIMIENTO DE REDES INTERNAS DE TELECOMUNICACIONES | R27: PRESENCIAL | S27: 45877 | T27: 46062 | U27: INTERVECTOR SAS | V27: CR 65A # 72A - 50 B/ LAS FLORES | W27: CAREPA | X27: intervector300424@gmail.com | Y27: JESUS MARIA GONZALEZ ZAMBRANO | Z27: 320 577 85 98
A28: Yolanda Berrío | B28: Pasantía | C28: jg0563005@gmail.com | D28: CC | E28: 1001670094 | F28: GONZALEZ | G28: CHIQUILLO | H28: JERSON JESUS | I28: Jerson Jesus Gonzalez Chiquillo | J28: M | K28: ANTIOQUIA | L28: TURBO | M28: V/ COLDESA | N28: 3004256110 | O28: SAVIA SALUD | P28: 3012698 | Q28: PRODUCCION AGROPECUARIA | R28: PRESENCIAL | S28: 45880 | T28: 46063 | U28: ASI ES LA VIDA | V28: V/COLDESA | W28: TURBO | X28: mavilgonzalez7@gmail.com | Y28: MAVIL ROSARIO GONZALEZ | Z28: 3146105921
A29: Maria del Rosari Jaramillo | B29: Pasantía | C29: MAYERLYSICUESTA@GMAIL. | D29: CC | E29: 1001026387 | F29: MURILLO | G29: CUESTA | H29: MAYERLYS | I29: Mayerlys Murillo Cuesta | J29: F | K29: ANTIOQUIA | L29: TURBO | M29: OBRERO | N29: 3147293135 | O29: SURA | P29: 3026343 | Q29: .ATENCION INTEGRAL A LA PRIMERA INFANCIA | R29: PRESENCIAL | S29: 45882 | T29: 46066 | U29: FUNDACIÓN DIOCESANA COMPARTIR | V29: BARRIO CHINITA, CARRERA 98 # 100 - 51 | W29: APARTADÓ ANTIOQUIA | X29: compartirturbo@gmail.com | Y29: DIANA TIRADO HERNANDEZ | Z29: 3148943614
A30: Maria del Rosari Jaramillo | B30: Pasantía | C30: amparomartinezpin@gmail.com | D30: CC | E30: 1193587554 | F30: MARTINEZ | G30: PINO | H30: AMPARO | I30: Amparo Martinez Pino | J30: F | K30: ANTIOQUIA | L30: TURBO | M30: BOSQUE | N30: 3136451051 | O30: COOSALUD | P30: 3067834 | Q30: .ATENCION INTEGRAL A LA PRIMERA INFANCIA | R30: PRESENCIAL | S30: 45857 | T30: 46072 | U30: INSTITUCION EDUCATIVA SAN MARTIN | V30: juan xxIII calle 100 crr 15 | W30: TURBO | X30: iesanmartin@turboeducado.edu.coo | Y30: YULIANA ROLDAN | Z30: 3146426803
A31: Virtual | B31: Vinc. Lab. | C31: DRMECADO@SOY.SENA.EDU.CO | D31: CC | E31: 1015425132 | F31: MERCADO | G31: VILLARREAL | H31: DOUGLAS RAFAEL | I31: Douglas Rafael Mercado Villarreal | J31: M | K31: ANTIOQUIA | N31: 3028452504 | O31: SANITAS | P31: 2834803 | Q31: ANALISIS Y DESARROLLO DE SOFTWARE. | R31: VIRTUAL | S31: 45857 | T31: 46072 | U31: HYPER INGENIEROS SAS | V31: CARRERA 97 A - 75 - 26 | W31: BOGOTA D.C | X31: ceo@hyperingenieros.com.co | Y31: LILIANA GUTIERREZ | Z31: 3144740054
A32: Maria del Rosari Jaramillo | B32: Pasantía | C32: chiky.10@hotmail.es | D32: CC | E32: 1038807037 | F32: FLOREZ | G32: MARTINEZ | H32: NERLIS | I32: Nerlis Florez Martinez | J32: F | K32: Antioquia | L32: Chigorodo | M32: Barrio la paz | N32: 3116408323 | O32: Nueva esp | P32: 3067834 | Q32: .ATENCION INTEGRAL A LA PRIMERA INFANCIA | R32: PRESENCIAL | S32: 45889 | T32: 46073 | U32: Jardin Grandes Exploradores | V32: cl-95#109-30 b/ los olivos | W32: chigorodo | X32: jigrandesexploradores@gmail.com | Y32: karen liseth jaramilo - Administradora | Z32: 3148122428
A33: Maria del Rosari Jaramillo | B33: Pasantía | C33: montalvoeli87@gmail.com | D33: CC | E33: 1038806475 | F33: MONTALVO | G33: ORTEGA | H33: ELI JOHANA | I33: Eli Johana Montalvo Ortega | J33: F | K33: Antioquia | L33: Chigorodo | M33: cra 102a calle84a 03 | N33: 3215011590 | O33: savia salud | P33: 3067834 | Q33: .ATENCION INTEGRAL A LA PRIMERA INFANCIA | R33: PRESENCIAL | S33: 45889 | T33: 46073 | U33: Jardin Grandes Axploradores | V33: cl-95#109-30 b/ los olivos | W33: chigorodo | X33: jigrandesexploradores@gmail.com | Y33: karen liseth jaramillo- Administradora | Z33: 3148122428
A34: Virtual | B34: Pasantía | C34: karotr2017@hotmail.com | D34: CC | E34: 52759494 | F34: TRIANA | G34: RODRIGUEZ | H34: SARA CAROLINA | I34: =PROPER(H34&" "&F34&" "&G34) -> Sara Carolina Triana Rodriguez | J34: F | K34: Tolima | L34: Carmen de Apicalá | M34: Cra. 3 #5-52 | N34: 3134003071 | O34: Famisanar | P34: 2879779 | Q34: DESARROLLO PUBLICITARIO | R34: VIRTUAL | S34: 21/08/2025 | T34: 46073 | U34: GUMO INGENIERIA S.A.S. | V34: Cra 16 A # 78 - 55 of. 303 | W34: Bogota D.C. | X34: ing.mogollon27@gmail.com | Y34: Zidderman Mogollon | Z34: 3124457403
A35: Julian Moreno | B35: Pasantía | C35: VALENTINAHERRERAFRANCO3@GMAIL.COM | D35: CC | E35: 1039090627 | F35: HERRERA | G35: FRANCO | H35: VALENTINA | I35: Valentina Herrera Franco | J35: F | K35: ANTIOQUIA | L35: NECOCLI | M35: CRR 43 #51-01 BRR PARROQUIAL | N35: 3135361561 | O35: SAVIA SALUD | P35: 2923976 | Q35: SERVICIOS FARMACEUTICOS | R35: PRESENCIAL | S35: 45896 | T35: 46080 | U35: DROGUERIA COMERCIAL | V35: CRR 44 #51-11 | W35: NECOCLI | X35: AUX.CONTABILIDAD@DROGUERIACOMERCIAL.COM | Y35: LUIS GUILLERMO GARCIA | Z35: 3104136592
A36: Maria del Rosari Jaramillo | B36: Pasantía | C36: danielacortesortiz38@gmail.com | D36: CC | E36: 1038799879 | F36: CORTES | G36: ORTIZ | H36: DANIELA | I36: Daniela Cortes Ortiz | J36: F | K36: Antioquia | L36: Chigorodo | M36: Balsos | N36: 3225235978 | O36: Savia salud | P36: 3067834 | Q36: .ATENCION INTEGRAL A LA PRIMERA INFANCIA | R36: PRESENCIAL | S36: 45896 | T36: 46080 | U36: Jardin Grandes Explradores | V36: Cl-95#109-30B/los Olivos | W36: Chigorodo | X36: jigrandreexploradores@gmail.com | Y36: Karen Liseth Jaramllo - Administradora | Z36: 3148122428
A37: Maria del Rosari Jaramillo | B37: Pasantía | C37: Paolausuga056@gmail.com | D37: CC | E37: 1010130039 | F37: USUGA | G37: OSORIO | H37: YENI PAOLA | I37: Yeni Paola Usuga Osorio | J37: F | K37: ANTIOQUIA | L37: CHIGORODO | M37: Barrio Las Tablitas | N37: 3218031545 | O37: savia salud | P37: 3067834 | Q37: .ATENCION INTEGRAL A LA PRIMERA INFANCIA | R37: PRESENCIAL | S37: 45901 | T37: 46081 | U37: I.E Juan Evangelista Berrio | V37: CALLE 8A B N° 91 -45 | W37: CHIGORODÓ | X37: talleresjuanevangelista@gmail.com | Y37: Leydy Lorena Ibarguen Ledesma | Z37: 3147022155
A38: Abel Valderrama | B38: Proy. Prod. | C38: yiscarpereamorenomosquera@gmail.com | D38: CC | E38: 1003969468 | F38: CORREA | G38: MURILLO | H38: JHON EDISON | I38: Jhon Edison Correa Murillo | J38: M | K38: Antioquia | L38: Vigia del fuerte | M38: barrio achinal | N38: 3226222249 | O38: savia salud | P38: 3001943 | Q38: SISTEMAS TELEINFORMÁTICOS | R38: PRESENCIAL | S38: 45901 | T38: 46081 | U38: ASOFUTEC | V38: CARRERA 2 | W38: VIGIA DEL FUER | X38: Asofutec44@gmail.com | Y38: DEIVER HEREDIA CHA | Z38: 3023636683
A39: Marcelino Gonzalez | B39: Vinc. Lab. | C39: sebasespitia97@gmail.com | D39: CC | E39: 1193553863 | F39: ESPITIA | G39: CAMAÑO | H39: JUAN SEBASTIAN | I39: Juan Sebastian Espitia Camaño | J39: M | K39: Antioquia | L39: Chigorodó | M39: cll86a 104-24 B/ el paraiso | N39: 3012097030 | O39: Sura | P39: 3206188 | Q39: PRODUCCION AGROPECUARIA | R39: PRESENCIAL | S39: 45900 | T39: 46081 | U39: Promotora Palmera de Antioquia | V39: Cr 80 Cl 80 Lc 116 cc Las Playas | W39: Carepa | X39: recepcion.ppa@hotmail.com | Y39: Juan Ballesta | Z39: 3128926382
A40: Marcelino Gonzalez | B40: Vinc. Lab. | C40: edwinmadera3@gmail.com | D40: CC | E40: 1038809619 | F40: MADERA | G40: VELASQUEZ | H40: EDWIN ANTONIO | I40: Edwin Antonio Madera Velasquez | J40: M | K40: Antioquia | L40: Chigorodó | M40: Cll94b nro 108-80 | N40: 3145920178 | O40: Sura | P40: 3206188 | Q40: PRODUCCION AGROPECUARIA | R40: PRESENCIAL | S40: 45697 | T40: 46083 | U40: UNALTRAPEC | V40: Cll 95. Nro 95c - 23 - B/ Linares | W40: Chigorodó Ant | X40: unaltrachigorodo@gmail.com | Y40: Bladimir Perez | Z40: 3122985629
A41: Julian Moreno | B41: Pasantía | C41: STEFANIATEHERAN960@GMAIL.COM | D41: CC | E41: 1001589381 | F41: THERAN | G41: VARGAS | H41: STEFANNIA | I41: Stefannia Theran Vargas | J41: F | K41: ANTIOQUIA | L41: NECOCLI | M41: VEREDA BOTIJUELA | N41: 3004690176 | O41: NUEVA EPS | P41: 2923976 | Q41: SERVICIOS FARMACEUTICOS | R41: PRESENCIAL | S41: 45905 | T41: 46086 | U41: DROGUERIA COMERCIAL | V41: CRR 44 #51-11 | W41: NECOCLI | X41: AUX.CONTABILIDAD@DROGUERIACOMERCIAL.COM | Y41: LUIS GUILLERMO GARCIA | Z41: 3104136592
...

Sheet Instructores 2026
A1: LISTADO DE INSTRUCTORES DE SEGUIMIENTO A ETAPA PRODUCTIVA DE 2026
A2: Coordinación | B2: Nombre instructor | C2: Formación | D2: Teléfono | E2: Correo corp | F2: Tipo de vinc. | G2: % dedic | H2: Cant Aprend
A3: Aida | B3: Abel De La Cruz Valderrama Palacio | C3: Sistemas | D3: 312 768 8079 | E3: advalderrama@sena.edu.co | F3: Contratista | G3: 100 | H3: 80
A4: Aida | B4: Andrés Felipe Henao Núñez | C4: Motores | D4: 301 280 6637 | E4: afhenao@sena.edu.co | F4: Contratista | G4: 30 | H4: 24
A5: Aida | B5: Cindy Johanna Gualtero Restrepo | C5: Gráficos | D5: 323 567 5626 | E5: cjgualtero@sena.edu.co | F5: Contratista | G5: 100 | H5: 80
A6: Aida | B6: Moises Enrique Garay Castro | C6: Gráficos | D6: 316 851 3077 | E6: mgarayc@sena.edu.co
A7: Aida | B7: Carlos Felipe Negrete Petro | C7: Electricidad | D7: 314 654 9006 | E7: cnegretep@sena.edu.co | F7: Planta | G7: 80 | H7: 52
A8: Aida | B8: Claudia Paricia Villareal Cárdenas | C8: Virtualidad | D8: 310 809 9637 | E8: cpvillareal@sena.edu.co
A9: Yanny Rivas | B9: Paola Andrea Londoño Guzmán | C9: SST | D9: 314 672 5672 | E9: plondono@sena.edu.co | F9: Planta | G9: 100 | H9: 65
A10: Yanny Rivas | B10: Silvia Paola Chaverra Durán | C10: administracion | D10: 314 600 6451 | E10: spchaverra@sena.edu.co | F10: Contratista | G10: 100 | H10: 80
A11: Yanny Rivas | B11: Aldwin Morelo Villa | C11: Adm y logis | D11: 300 254 1479 | E11: amorelo@sena.edu.co | F11: Contratista | G11: 100 | H11: 80
A12: Yanny Rivas | B12: Daisy Suheiry Quejada Durán | C12: Contadora | D12: 313 743 3102 | E12: dquejada@sena.edu.co | F12: Contratista | G12: 100 | H12: 80
A13: Yanny Rivas | B13: Jaime Andrés Ruiz Ortega | C13: Comercio | D13: 310 894 2666 | E13: jaruizo@sena.edu.co | F13: Contratista | G13: 30 | H13: 24
A14: Yanny Rivas | B14: Lucy Liliana Pernett Ospina | C14: Hoteleria | D14: 310 898 1729 | E14: lpernett@sena.edu.co | F14: Planta | G14: 100 | H14: 65
A15: Maricela | B15: Flor Elene Jiménez Lopera | C15: agric sost | D15: 300 632 6923 | E15: fejimenezl@sena.edu.co | F15: Planta | G15: 100 | H15: 65
A16: Maricela | B16: Marcelino González Vertel | C16: Agronomia | D16: 320 724 8288 | E16: mgonzalesve@sena.edu.co | F16: Contratista | G16: 100 | H16: 80
A17: Maricela | B17: Erika Durango Martínez | C17: MVZ | D17: 314 835 7426 | E17: eydurango@sena.edu.co
A18: Maricela | B18: Gustavo Andrés Cataño Cortes | C18: MVZ | D18: 321 626 8578 | E18: gcatanoc@sena.edu.co | F18: Contratista | G18: 60 | H18: 48
A19: Maricela | B19: Nelvis Margoth Barboza Rivera | C19: Farmacia | D19: 302 243 9155 | E19: nmbarboza@sena.edu.co | F19: Contratista | G19: 100 | H19: 80
A20: Maricela | B20: Julián Mauricio Moreno Flórez | C20: Quimico amb | D20: 312 786 4424 | E20: jmmorenof@sena.edu.co | F20: Contratista | G20: 100 | H20: 80
A21: Maricela | B21: Yorger Moreno Agualimpia | C21: Ambiental | D21: 311 322 5327 | E21: ymorenoa@sena.edu.co | F21: Contratista | G21: 100 | H21: 80
A22: Maricela | B22: Maria del Rosari Jaramillo Hernández | C22: Infancia | D22: 314 675 7233 | E22: mjaramillohe@sena.edu.co | F22: Contratista | G22: 25 | H22: 20
A23: Maricela | B23: Viviana Lizeth Robledo Bello | C23: Deportes | D23: 320 666 9480 | E23: vrobledo@sena.edu.co | F23: Contratista | G23: 100 | H23: 80
A24: Osman | B24: Marco Antonio García Peña | C24: Deportes | D24: 320 769 1560 | E24: mgarciap@sena.edu.co | F24: Planta
A25: Osman | B25: Yerlis Hernández Martínez | C25: Deportes | D25: 320 571 1276 | E25: yhernandezm@sena.edu.co | F25: Contratista | G25: 50 | H25: 40
A26: Osman Campesena | B26: Dina Luz Dorado Pérez | D26: 311 683 0354 | E26: ddoradop@sena.edu.co | F26: Contratista
A27: Osman Campesena | B27: Yolanda Berrío | D27: 312 728 2722 | E27: yberrio@sena.edu.co | F27: Contratista
A28: Osman Campesena | B28: Aristides Maturana Ramos | D28: 314 725 2697 | E28: amaturana@sena.edu.co
A29: Osman Campesena | B29: Fabián Andrés Valencia Castrillón | D29: 314 764 6245 | E29: favalenciac@sena.edu.co | F29: Contratista
A30: Osman Campesena | B30: Julián andrés Lugo Castañeda | D30: 313 587 7277 | E30: jlugo@sena.edu.co | F30: Contratista

Sheet Perfilamiento
A1: FORMACIONES POR COORDINACIÓN
A3: FORMACIÓN | B3: PERFILA | C3: COORDINADOR | D3: APOYO DE COORDINACIÓN - CELULAR
A4: ACTIVIDAD FISICA | B4: ssepulvedad@sena.edu.co | C4: OSMAN JOSUE PEREA CASTRO
A5: ANALISIS Y DESARROLLO DE SISTEMAS DE INFORMACION | B5: bjmontoya@sena.edu.co | C5: AIDA LUZ BALLESTEROS | D5: Yorledis Leon Carbrera - 313 248 4064
A6: ANALISIS Y DESARROLLO DE SOFTWARE | B6: bjmontoya@sena.edu.co | C6: AIDA LUZ BALLESTEROS | D6: Yorledis Leon Carbrera - 313 248 4064
A7: APOYO ADMINISTRATIVO EN SALUD. | B7: scalvarez@sena.edu.co | C7: MARICELA BARRERA MONTANEZ | D7: Leidy Borquez - 310 538 7274
A8: ASISTENCIA ADMINISTRATIVA . | B8: jmosquera@sena.edu.co | C8: YANNY RIVAS LONDOÑO | D8: Valentina Viloria - 310 354 6731
A9: ASISTENCIA EN ORGANIZACION DE ARCHIVOS . | B9: jmosquera@sena.edu.co | C9: YANNY RIVAS LONDOÑO | D9: Valentina Viloria - 310 354 6731
A10: ASISTENCIA PARA LA INTELIGENCIA EMPRESARIAL | B10: jmosquera@sena.edu.co | C10: YANNY RIVAS LONDOÑO | D10: Valentina Viloria - 310 354 6731
A11: ATENCION INTEGRAL A LA PRIMERA INFANCIA | B11: scalvarez@sena.edu.co | C11: MARICELA BARRERA MONTANEZ | D11: Leidy Borquez - 310 538 7274
A12: ATENCION INTEGRAL AL CLIENTE | B12: jmosquera@sena.edu.co | C12: YANNY RIVAS LONDOÑO | D12: Valentina Viloria - 310 354 6731
A13: AUXILIAR EN COCINA | B13: jmosquera@sena.edu.co | C13: YANNY RIVAS LONDOÑO | D13: Valentina Viloria - 310 354 6731
A14: COCINA | B14: jmosquera@sena.edu.co | C14: YANNY RIVAS LONDOÑO | D14: Valentina Viloria - 310 354 6731
A15: COMERCIALIZACION DE PRODUCTOS MASIVOS | B15: jmosquera@sena.edu.co | C15: YANNY RIVAS LONDOÑO | D15: Valentina Viloria - 310 354 6731
A16: CONSERVACION DE RECURSOS NATURALES | B16: scalvarez@sena.edu.co | C16: MARICELA BARRERA MONTANEZ | D16: Leidy Borquez - 310 538 7274
... A26: DESARROLLO PUBLICITARIO | B26: bjmontoya@sena.edu.co | C26: AIDA LUZ BALLESTEROS | D26: Yorledis Leon Carbrera - 313 248 4064
A27: EJECUCION DE PROGRAMAS DEPORTIVOS | B27: ssepulvedad@sena.edu.co | C27: OSMAN JOSUE PEREA CASTRO
A28: ENTRENAMIENTO DEPORTIVO | B28: ssepulvedad@sena.edu.co | C28: OSMAN JOSUE PEREA CASTRO
A29: GESTIÓN ADMINISTRATIVA | B29: jmosquera@sena.edu.co | C29: YANNY RIVAS LONDOÑO | D29: Valentina Viloria - 310 354 6731
